{
 "cells": [
  {
   "cell_type": "code",
   "execution_count": 16,
   "metadata": {},
   "outputs": [
    {
     "data": {
      "text/html": [
       "<iframe id=\"igraph\" scrolling=\"no\" style=\"border:none;\" seamless=\"seamless\" src=\"https://plot.ly/~Python-Demo-Account/17418.embed\" height=\"900px\" width=\"800px\"></iframe>"
      ],
      "text/plain": [
       "<plotly.tools.PlotlyDisplay object>"
      ]
     },
     "execution_count": 16,
     "metadata": {},
     "output_type": "execute_result"
    }
   ],
   "source": [
    "import plotly.plotly as py\n",
    "import plotly.graph_objs as go\n",
    "from plotly.tools import FigureFactory as FF\n",
    "\n",
    "import json\n",
    "import numpy as np\n",
    "import pandas as pd\n",
    "\n",
    "df = pd.read_csv('https://raw.githubusercontent.com/plotly/datasets/master/volcano.csv')\n",
    "\n",
    "data = [go.Surface(z=df.values.tolist(), colorscale='Viridis')]\n",
    "\n",
    "layout = go.Layout(\n",
    "    width=800,\n",
    "    height=900,\n",
    "    autosize=False,\n",
    "    margin=dict(t=0, b=0, l=0, r=0),\n",
    "    scene=dict(\n",
    "        xaxis=dict(\n",
    "            gridcolor='rgb(255, 255, 255)',\n",
    "            zerolinecolor='rgb(255, 255, 255)',\n",
    "            showbackground=True,\n",
    "            backgroundcolor='rgb(230, 230,230)'\n",
    "        ),\n",
    "        yaxis=dict(\n",
    "            gridcolor='rgb(255, 255, 255)',\n",
    "            zerolinecolor='rgb(255, 255, 255)',\n",
    "            showbackground=True,\n",
    "            backgroundcolor='rgb(230, 230, 230)'\n",
    "        ),\n",
    "        zaxis=dict(\n",
    "            gridcolor='rgb(255, 255, 255)',\n",
    "            zerolinecolor='rgb(255, 255, 255)',\n",
    "            showbackground=True,\n",
    "            backgroundcolor='rgb(230, 230,230)'\n",
    "        ),\n",
    "        aspectratio = dict(x=1, y=1, z=0.7),\n",
    "        aspectmode = 'manual'\n",
    "    )\n",
    ")\n",
    "\n",
    "updatemenus=list([\n",
    "    dict(\n",
    "        buttons=list([   \n",
    "            dict(\n",
    "                args=['type', 'surface'],\n",
    "                label='3D Surface',\n",
    "                method='restyle'\n",
    "            ),\n",
    "            dict(\n",
    "                args=['type', 'heatmap'],\n",
    "                label='Heatmap',\n",
    "                method='restyle'\n",
    "            )             \n",
    "        ]),\n",
    "        direction = 'down',\n",
    "        pad = {'r': 10, 't': 10},\n",
    "        showactive = True,\n",
    "        x = 0.1,\n",
    "        xanchor = 'left',\n",
    "        y = 1.1,\n",
    "        yanchor = 'top' \n",
    "    ),\n",
    "])\n",
    "\n",
    "annotations = list([\n",
    "    dict(text='Trace type:', x=0, y=1.085, yref='paper', align='left', showarrow=False)\n",
    "])\n",
    "layout['updatemenus'] = updatemenus\n",
    "layout['annotations'] = annotations\n",
    "\n",
    "fig = dict(data=data, layout=layout)\n",
    "py.iplot(fig, filename='cmocean-picker-one-dropdown')"
   ]
  },
  {
   "cell_type": "code",
   "execution_count": 23,
   "metadata": {},
   "outputs": [
    {
     "data": {
      "text/plain": [
       "Graph(id='my-graph', figure={'data': [{'type': 'bar', 'x': [1995, 1996, 1997, 1998, 1999, 2000, 2001, 2002, 2003, 2004, 2005, 2006, 2007, 2008, 2009, 2010, 2011, 2012], 'y': [219, 146, 112, 127, 124, 180, 236, 207, 236, 263, 350, 430, 474, 526, 488, 537, 500, 439], 'name': 'Rest of world', 'marker': {'color': 'rgb(55, 83, 109)'}}, {'type': 'bar', 'x': [1995, 1996, 1997, 1998, 1999, 2000, 2001, 2002, 2003, 2004, 2005, 2006, 2007, 2008, 2009, 2010, 2011, 2012], 'y': [16, 13, 10, 11, 28, 37, 43, 55, 56, 88, 105, 156, 270, 299, 340, 403, 549, 499], 'name': 'China', 'marker': {'color': 'rgb(26, 118, 255)'}}], 'layout': {'title': 'US Export of Plastic Scrap', 'showlegend': True, 'legend': {'x': 0, 'y': 1.0}, 'margin': {'l': 40, 'r': 0, 't': 40, 'b': 30}}}, style={'height': 300})"
      ]
     },
     "execution_count": 23,
     "metadata": {},
     "output_type": "execute_result"
    }
   ],
   "source": []
  },
  {
   "cell_type": "code",
   "execution_count": 25,
   "metadata": {},
   "outputs": [
    {
     "name": "stderr",
     "output_type": "stream",
     "text": [
      " * Running on http://127.0.0.1:8050/ (Press CTRL+C to quit)\n",
      "127.0.0.1 - - [15/Apr/2018 22:52:05] \"GET / HTTP/1.1\" 200 -\n",
      "127.0.0.1 - - [15/Apr/2018 22:52:07] \"GET /_dash-layout HTTP/1.1\" 200 -\n",
      "127.0.0.1 - - [15/Apr/2018 22:52:07] \"GET /_dash-dependencies HTTP/1.1\" 200 -\n",
      "/usr/local/lib/python3.6/site-packages/pandas_datareader/google/daily.py:40: UnstableAPIWarning:\n",
      "\n",
      "\n",
      "The Google Finance API has not been stable since late 2017. Requests seem\n",
      "to fail at random. Failure is especially common when bulk downloading.\n",
      "\n",
      "\n",
      "[2018-04-15 22:52:09,062] ERROR in app: Exception on /_dash-update-component [POST]\n",
      "Traceback (most recent call last):\n",
      "  File \"/usr/local/lib/python3.6/site-packages/flask/app.py\", line 1982, in wsgi_app\n",
      "    response = self.full_dispatch_request()\n",
      "  File \"/usr/local/lib/python3.6/site-packages/flask/app.py\", line 1614, in full_dispatch_request\n",
      "    rv = self.handle_user_exception(e)\n",
      "  File \"/usr/local/lib/python3.6/site-packages/flask/app.py\", line 1517, in handle_user_exception\n",
      "    reraise(exc_type, exc_value, tb)\n",
      "  File \"/usr/local/lib/python3.6/site-packages/flask/_compat.py\", line 33, in reraise\n",
      "    raise value\n",
      "  File \"/usr/local/lib/python3.6/site-packages/flask/app.py\", line 1612, in full_dispatch_request\n",
      "    rv = self.dispatch_request()\n",
      "  File \"/usr/local/lib/python3.6/site-packages/flask/app.py\", line 1598, in dispatch_request\n",
      "    return self.view_functions[rule.endpoint](**req.view_args)\n",
      "  File \"/usr/local/lib/python3.6/site-packages/dash/dash.py\", line 556, in dispatch\n",
      "    return self.callback_map[target_id]['callback'](*args)\n",
      "  File \"/usr/local/lib/python3.6/site-packages/dash/dash.py\", line 513, in add_context\n",
      "    output_value = func(*args, **kwargs)\n",
      "  File \"<ipython-input-25-9971a340fd89>\", line 28, in update_graph\n",
      "    start=dt(2017, 1, 1), end=dt.now())\n",
      "  File \"/usr/local/lib/python3.6/site-packages/pandas_datareader/data.py\", line 315, in DataReader\n",
      "    session=session).read()\n",
      "  File \"/usr/local/lib/python3.6/site-packages/pandas_datareader/base.py\", line 206, in read\n",
      "    params=self._get_params(self.symbols))\n",
      "  File \"/usr/local/lib/python3.6/site-packages/pandas_datareader/base.py\", line 84, in _read_one_data\n",
      "    out = self._read_url_as_StringIO(url, params=params)\n",
      "  File \"/usr/local/lib/python3.6/site-packages/pandas_datareader/base.py\", line 95, in _read_url_as_StringIO\n",
      "    response = self._get_response(url, params=params)\n",
      "  File \"/usr/local/lib/python3.6/site-packages/pandas_datareader/base.py\", line 155, in _get_response\n",
      "    raise RemoteDataError(msg)\n",
      "pandas_datareader._utils.RemoteDataError: Unable to read URL: https://finance.google.com/finance/historical?q=COKE&startdate=Jan+01%2C+2017&enddate=Apr+15%2C+2018&output=csv\n",
      "Response Text:\n",
      "b'<html><head><meta http-equiv=\"content-type\" content=\"text/html; charset=utf-8\"/><title>Sorry...</title><style> body { font-family: verdana, arial, sans-serif; background-color: #fff; color: #000; }</style></head><body><div><table><tr><td><b><font face=sans-serif size=10><font color=#4285f4>G</font><font color=#ea4335>o</font><font color=#fbbc05>o</font><font color=#4285f4>g</font><font color=#34a853>l</font><font color=#ea4335>e</font></font></b></td><td style=\"text-align: left; vertical-align: bottom; padding-bottom: 15px; width: 50%\"><div style=\"border-bottom: 1px solid #dfdfdf;\">Sorry...</div></td></tr></table></div><div style=\"margin-left: 4em;\"><h1>We\\'re sorry...</h1><p>... but your computer or network may be sending automated queries. To protect our users, we can\\'t process your request right now.</p></div><div style=\"margin-left: 4em;\">See <a href=\"https://support.google.com/websearch/answer/86640\">Google Help</a> for more information.<br/><br/></div><div style=\"text-align: center; border-top: 1px solid #dfdfdf;\"><a href=\"https://www.google.com\">Google Home</a></div></body></html>'\n",
      "127.0.0.1 - - [15/Apr/2018 22:52:09] \"POST /_dash-update-component HTTP/1.1\" 500 -\n",
      "127.0.0.1 - - [15/Apr/2018 22:52:09] \"GET /favicon.ico HTTP/1.1\" 200 -\n",
      "[2018-04-15 22:52:12,638] ERROR in app: Exception on /_dash-update-component [POST]\n",
      "Traceback (most recent call last):\n",
      "  File \"/usr/local/lib/python3.6/site-packages/flask/app.py\", line 1982, in wsgi_app\n",
      "    response = self.full_dispatch_request()\n",
      "  File \"/usr/local/lib/python3.6/site-packages/flask/app.py\", line 1614, in full_dispatch_request\n",
      "    rv = self.handle_user_exception(e)\n",
      "  File \"/usr/local/lib/python3.6/site-packages/flask/app.py\", line 1517, in handle_user_exception\n",
      "    reraise(exc_type, exc_value, tb)\n",
      "  File \"/usr/local/lib/python3.6/site-packages/flask/_compat.py\", line 33, in reraise\n",
      "    raise value\n",
      "  File \"/usr/local/lib/python3.6/site-packages/flask/app.py\", line 1612, in full_dispatch_request\n",
      "    rv = self.dispatch_request()\n",
      "  File \"/usr/local/lib/python3.6/site-packages/flask/app.py\", line 1598, in dispatch_request\n",
      "    return self.view_functions[rule.endpoint](**req.view_args)\n",
      "  File \"/usr/local/lib/python3.6/site-packages/dash/dash.py\", line 556, in dispatch\n",
      "    return self.callback_map[target_id]['callback'](*args)\n",
      "  File \"/usr/local/lib/python3.6/site-packages/dash/dash.py\", line 513, in add_context\n",
      "    output_value = func(*args, **kwargs)\n",
      "  File \"<ipython-input-25-9971a340fd89>\", line 28, in update_graph\n",
      "    start=dt(2017, 1, 1), end=dt.now())\n",
      "  File \"/usr/local/lib/python3.6/site-packages/pandas_datareader/data.py\", line 315, in DataReader\n",
      "    session=session).read()\n",
      "  File \"/usr/local/lib/python3.6/site-packages/pandas_datareader/base.py\", line 206, in read\n",
      "    params=self._get_params(self.symbols))\n",
      "  File \"/usr/local/lib/python3.6/site-packages/pandas_datareader/base.py\", line 84, in _read_one_data\n",
      "    out = self._read_url_as_StringIO(url, params=params)\n",
      "  File \"/usr/local/lib/python3.6/site-packages/pandas_datareader/base.py\", line 95, in _read_url_as_StringIO\n",
      "    response = self._get_response(url, params=params)\n",
      "  File \"/usr/local/lib/python3.6/site-packages/pandas_datareader/base.py\", line 155, in _get_response\n",
      "    raise RemoteDataError(msg)\n",
      "pandas_datareader._utils.RemoteDataError: Unable to read URL: https://finance.google.com/finance/historical?q=TSLA&startdate=Jan+01%2C+2017&enddate=Apr+15%2C+2018&output=csv\n",
      "Response Text:\n",
      "b'<html><head><meta http-equiv=\"content-type\" content=\"text/html; charset=utf-8\"/><title>Sorry...</title><style> body { font-family: verdana, arial, sans-serif; background-color: #fff; color: #000; }</style></head><body><div><table><tr><td><b><font face=sans-serif size=10><font color=#4285f4>G</font><font color=#ea4335>o</font><font color=#fbbc05>o</font><font color=#4285f4>g</font><font color=#34a853>l</font><font color=#ea4335>e</font></font></b></td><td style=\"text-align: left; vertical-align: bottom; padding-bottom: 15px; width: 50%\"><div style=\"border-bottom: 1px solid #dfdfdf;\">Sorry...</div></td></tr></table></div><div style=\"margin-left: 4em;\"><h1>We\\'re sorry...</h1><p>... but your computer or network may be sending automated queries. To protect our users, we can\\'t process your request right now.</p></div><div style=\"margin-left: 4em;\">See <a href=\"https://support.google.com/websearch/answer/86640\">Google Help</a> for more information.<br/><br/></div><div style=\"text-align: center; border-top: 1px solid #dfdfdf;\"><a href=\"https://www.google.com\">Google Home</a></div></body></html>'\n",
      "127.0.0.1 - - [15/Apr/2018 22:52:12] \"POST /_dash-update-component HTTP/1.1\" 500 -\n",
      "[2018-04-15 22:52:14,898] ERROR in app: Exception on /_dash-update-component [POST]\n",
      "Traceback (most recent call last):\n",
      "  File \"/usr/local/lib/python3.6/site-packages/flask/app.py\", line 1982, in wsgi_app\n",
      "    response = self.full_dispatch_request()\n",
      "  File \"/usr/local/lib/python3.6/site-packages/flask/app.py\", line 1614, in full_dispatch_request\n",
      "    rv = self.handle_user_exception(e)\n",
      "  File \"/usr/local/lib/python3.6/site-packages/flask/app.py\", line 1517, in handle_user_exception\n",
      "    reraise(exc_type, exc_value, tb)\n",
      "  File \"/usr/local/lib/python3.6/site-packages/flask/_compat.py\", line 33, in reraise\n",
      "    raise value\n",
      "  File \"/usr/local/lib/python3.6/site-packages/flask/app.py\", line 1612, in full_dispatch_request\n",
      "    rv = self.dispatch_request()\n",
      "  File \"/usr/local/lib/python3.6/site-packages/flask/app.py\", line 1598, in dispatch_request\n",
      "    return self.view_functions[rule.endpoint](**req.view_args)\n",
      "  File \"/usr/local/lib/python3.6/site-packages/dash/dash.py\", line 556, in dispatch\n",
      "    return self.callback_map[target_id]['callback'](*args)\n",
      "  File \"/usr/local/lib/python3.6/site-packages/dash/dash.py\", line 513, in add_context\n",
      "    output_value = func(*args, **kwargs)\n",
      "  File \"<ipython-input-25-9971a340fd89>\", line 28, in update_graph\n",
      "    start=dt(2017, 1, 1), end=dt.now())\n",
      "  File \"/usr/local/lib/python3.6/site-packages/pandas_datareader/data.py\", line 315, in DataReader\n",
      "    session=session).read()\n",
      "  File \"/usr/local/lib/python3.6/site-packages/pandas_datareader/base.py\", line 206, in read\n",
      "    params=self._get_params(self.symbols))\n",
      "  File \"/usr/local/lib/python3.6/site-packages/pandas_datareader/base.py\", line 84, in _read_one_data\n",
      "    out = self._read_url_as_StringIO(url, params=params)\n",
      "  File \"/usr/local/lib/python3.6/site-packages/pandas_datareader/base.py\", line 95, in _read_url_as_StringIO\n",
      "    response = self._get_response(url, params=params)\n",
      "  File \"/usr/local/lib/python3.6/site-packages/pandas_datareader/base.py\", line 155, in _get_response\n",
      "    raise RemoteDataError(msg)\n",
      "pandas_datareader._utils.RemoteDataError: Unable to read URL: https://finance.google.com/finance/historical?q=AAPL&startdate=Jan+01%2C+2017&enddate=Apr+15%2C+2018&output=csv\n",
      "Response Text:\n",
      "b'<html><head><meta http-equiv=\"content-type\" content=\"text/html; charset=utf-8\"/><title>Sorry...</title><style> body { font-family: verdana, arial, sans-serif; background-color: #fff; color: #000; }</style></head><body><div><table><tr><td><b><font face=sans-serif size=10><font color=#4285f4>G</font><font color=#ea4335>o</font><font color=#fbbc05>o</font><font color=#4285f4>g</font><font color=#34a853>l</font><font color=#ea4335>e</font></font></b></td><td style=\"text-align: left; vertical-align: bottom; padding-bottom: 15px; width: 50%\"><div style=\"border-bottom: 1px solid #dfdfdf;\">Sorry...</div></td></tr></table></div><div style=\"margin-left: 4em;\"><h1>We\\'re sorry...</h1><p>... but your computer or network may be sending automated queries. To protect our users, we can\\'t process your request right now.</p></div><div style=\"margin-left: 4em;\">See <a href=\"https://support.google.com/websearch/answer/86640\">Google Help</a> for more information.<br/><br/></div><div style=\"text-align: center; border-top: 1px solid #dfdfdf;\"><a href=\"https://www.google.com\">Google Home</a></div></body></html>'\n"
     ]
    },
    {
     "name": "stderr",
     "output_type": "stream",
     "text": [
      "127.0.0.1 - - [15/Apr/2018 22:52:14] \"POST /_dash-update-component HTTP/1.1\" 500 -\n"
     ]
    }
   ],
   "source": [
    "import numpy as np\n",
    "import pandas as pd\n",
    "import plotly\n",
    "import plotly.plotly as py\n",
    "from plotly.graph_objs import *\n",
    "import plotly.tools as tls\n",
    "from plotly.offline import download_plotlyjs, init_notebook_mode, plot, iplot\n",
    "\n",
    "from ipywidgets import widgets \n",
    "\n",
    "from IPython.display import display, clear_output, Image\n",
    "from plotly.widgets import GraphWidget\n",
    "\n",
    "#plotly.tools.set_credentials_file(username='wangqiwen', api_key='8r40jKGvIemGyOP1PEZ1')\n",
    "init_notebook_mode(connected=True)\n",
    "fig = py.get_figure('https://plot.ly/~jackp/8715', raw=True)\n",
    "iplot(fig)"
   ]
  },
  {
   "cell_type": "code",
   "execution_count": null,
   "metadata": {},
   "outputs": [],
   "source": []
  }
 ],
 "metadata": {
  "kernelspec": {
   "display_name": "Python 3",
   "language": "python",
   "name": "python3"
  },
  "language_info": {
   "codemirror_mode": {
    "name": "ipython",
    "version": 3
   },
   "file_extension": ".py",
   "mimetype": "text/x-python",
   "name": "python",
   "nbconvert_exporter": "python",
   "pygments_lexer": "ipython3",
   "version": "3.6.4"
  }
 },
 "nbformat": 4,
 "nbformat_minor": 2
}
